Job 1894301: Running on node(s) serv-[3315-3316]
Job 1894301: Started at 2025-06-12 11:08:52+0200
Monitor this job here: http://monitoring.pegasus.kl.dfki.de/d/slurm-job-details/job-details?var-jobid=1894301&from=1749719332000
srun: jobinfo: version v1.0.0
Job 1894301: Running on node(s) serv-[3315-3316]
Job 1894301: Started at 2025-06-12 11:08:53+0200
Monitor this job here: http://monitoring.pegasus.kl.dfki.de/d/slurm-job-details/job-details?var-jobid=1894301&from=1749719333000
Job 1894301: creating container for /netscratch/kpatil/container/SparseBEV.sqsh
Job 1894301: creating container for /netscratch/kpatil/container/SparseBEV.sqsh
Job 1894301: creating container for /netscratch/kpatil/container/SparseBEV.sqsh took 44.0 seconds
Job 1894301: creating container for /netscratch/kpatil/container/SparseBEV.sqsh took 44.0 seconds
WARNING:torch.distributed.run:
*****************************************
Setting OMP_NUM_THREADS environment variable for each process to be 1 in default, to avoid your system being overloaded, please further tune the variable for optimal performance in your application as needed. 
*****************************************
/usr/bin/python: can't open file 'tools/train.py': [Errno 2] No such file or directory
/usr/bin/python: can't open file 'tools/train.py': [Errno 2] No such file or directory
/usr/bin/python: can't open file 'tools/train.py': [Errno 2] No such file or directory
/usr/bin/python: can't open file 'tools/train.py': [Errno 2] No such file or directory
WARNING:torch.distributed.run:
*****************************************
Setting OMP_NUM_THREADS environment variable for each process to be 1 in default, to avoid your system being overloaded, please further tune the variable for optimal performance in your application as needed. 
*****************************************
/usr/bin/python: can't open file 'tools/train.py': [Errno 2] No such file or directory
/usr/bin/python: can't open file 'tools/train.py': [Errno 2] No such file or directory
/usr/bin/python: can't open file 'tools/train.py': [Errno 2] No such file or directory
/usr/bin/python: can't open file 'tools/train.py': [Errno 2] No such file or directory
ERROR:torch.distributed.elastic.multiprocessing.api:failed (exitcode: 2) local_rank: 0 (pid: 3224904) of binary: /usr/bin/python
Traceback (most recent call last):
  File "/usr/local/bin/torchrun", line 8, in <module>
    sys.exit(main())
  File "/usr/local/lib/python3.8/dist-packages/torch/distributed/elastic/multiprocessing/errors/__init__.py", line 346, in wrapper
    return f(*args, **kwargs)
  File "/usr/local/lib/python3.8/dist-packages/torch/distributed/run.py", line 794, in main
    run(args)
  File "/usr/local/lib/python3.8/dist-packages/torch/distributed/run.py", line 785, in run
    elastic_launch(
  File "/usr/local/lib/python3.8/dist-packages/torch/distributed/launcher/api.py", line 134, in __call__
    return launch_agent(self._config, self._entrypoint, list(args))
  File "/usr/local/lib/python3.8/dist-packages/torch/distributed/launcher/api.py", line 250, in launch_agent
    raise ChildFailedError(
torch.distributed.elastic.multiprocessing.errors.ChildFailedError: 
============================================================
tools/train.py FAILED
------------------------------------------------------------
Failures:
[1]:
  time      : 2025-06-12_11:09:44
  host      : serv-3315.kl.dfki.de
  rank      : 1 (local_rank: 1)
  exitcode  : 2 (pid: 3224905)
  error_file: <N/A>
  traceback : To enable traceback see: https://pytorch.org/docs/stable/elastic/errors.html
[2]:
  time      : 2025-06-12_11:09:44
  host      : serv-3315.kl.dfki.de
  rank      : 2 (local_rank: 2)
  exitcode  : 2 (pid: 3224906)
  error_file: <N/A>
  traceback : To enable traceback see: https://pytorch.org/docs/stable/elastic/errors.html
[3]:
  time      : 2025-06-12_11:09:44
  host      : serv-3315.kl.dfki.de
  rank      : 3 (local_rank: 3)
  exitcode  : 2 (pid: 3224907)
  error_file: <N/A>
  traceback : To enable traceback see: https://pytorch.org/docs/stable/elastic/errors.html
------------------------------------------------------------
Root Cause (first observed failure):
[0]:
  time      : 2025-06-12_11:09:44
  host      : serv-3315.kl.dfki.de
  rank      : 0 (local_rank: 0)
  exitcode  : 2 (pid: 3224904)
  error_file: <N/A>
  traceback : To enable traceback see: https://pytorch.org/docs/stable/elastic/errors.html
============================================================
ERROR:torch.distributed.elastic.multiprocessing.api:failed (exitcode: 2) local_rank: 0 (pid: 1177082) of binary: /usr/bin/python
Traceback (most recent call last):
  File "/usr/local/bin/torchrun", line 8, in <module>
    sys.exit(main())
  File "/usr/local/lib/python3.8/dist-packages/torch/distributed/elastic/multiprocessing/errors/__init__.py", line 346, in wrapper
    return f(*args, **kwargs)
  File "/usr/local/lib/python3.8/dist-packages/torch/distributed/run.py", line 794, in main
    run(args)
  File "/usr/local/lib/python3.8/dist-packages/torch/distributed/run.py", line 785, in run
    elastic_launch(
  File "/usr/local/lib/python3.8/dist-packages/torch/distributed/launcher/api.py", line 134, in __call__
    return launch_agent(self._config, self._entrypoint, list(args))
  File "/usr/local/lib/python3.8/dist-packages/torch/distributed/launcher/api.py", line 250, in launch_agent
    raise ChildFailedError(
torch.distributed.elastic.multiprocessing.errors.ChildFailedError: 
============================================================
tools/train.py FAILED
------------------------------------------------------------
Failures:
[1]:
  time      : 2025-06-12_11:09:44
  host      : serv-3316.kl.dfki.de
  rank      : 1 (local_rank: 1)
  exitcode  : 2 (pid: 1177083)
  error_file: <N/A>
  traceback : To enable traceback see: https://pytorch.org/docs/stable/elastic/errors.html
[2]:
  time      : 2025-06-12_11:09:44
  host      : serv-3316.kl.dfki.de
  rank      : 2 (local_rank: 2)
  exitcode  : 2 (pid: 1177084)
  error_file: <N/A>
  traceback : To enable traceback see: https://pytorch.org/docs/stable/elastic/errors.html
[3]:
  time      : 2025-06-12_11:09:44
  host      : serv-3316.kl.dfki.de
  rank      : 3 (local_rank: 3)
  exitcode  : 2 (pid: 1177085)
  error_file: <N/A>
  traceback : To enable traceback see: https://pytorch.org/docs/stable/elastic/errors.html
------------------------------------------------------------
Root Cause (first observed failure):
[0]:
  time      : 2025-06-12_11:09:44
  host      : serv-3316.kl.dfki.de
  rank      : 0 (local_rank: 0)
  exitcode  : 2 (pid: 1177082)
  error_file: <N/A>
  traceback : To enable traceback see: https://pytorch.org/docs/stable/elastic/errors.html
============================================================
srun: error: serv-3315: task 0: Exited with exit code 1
srun: error: serv-3316: task 1: Exited with exit code 1
